<?xml version='1.0' encoding='utf-8'?>
<robot name="worm">
  <link name="base_link">
    <visual>
      <origin rpy="0 0 0" xyz="0 0 0.05" />
      <geometry>
        <box size="0.5 0.5 0.1" />
      </geometry>
      <material name="blue">
        <color rgba="0.3 0.0 1 1.0" />
      </material>
    </visual>
    <collision>
      <origin rpy="0 0 0" xyz="0 0 0.05" />
      <geometry>
        <box size="0.5 0.5 0.1" />
      </geometry>
    </collision>
    <inertial>
      <mass value="0.0015" />
      <inertia ixx="1000" ixy="0" ixz="0" iyy="1000" iyz="0" izz="1000" />
      <origin rpy="0 0 0" xyz="0 0 0.05" />
    </inertial>
  </link>
  <link name="act0Seg0">
    <visual>
      <origin rpy="0 0 0" xyz="0 0 0.125" />
      <geometry>
        <box size="0.5 0.5 0.25" />
      </geometry>
      <material name="blue">
        <color rgba="0.3 0.0 1 1.0" />
      </material>
    </visual>
    <collision>
      <origin rpy="0 0 0" xyz="0 0 0.125" />
      <geometry>
        <box size="0.5 0.5 0.25" />
      </geometry>
    </collision>
    <inertial>
      <mass value="0.058230501033959554" />
      <inertia ixx="1" ixy="0" ixz="0" iyy="1" iyz="0" izz="1" />
      <origin rpy="0 0 0" xyz="0 0 0.125" />
    </inertial>
  </link>
  <joint name="base_link_to_act0Seg0" type="fixed">
    <parent link="base_link" />
    <child link="act0Seg0" />
    <origin rpy="0 0 0" xyz="0 0 0.1" />
    <axis xyz="1 0 0" />
  </joint>
  <link name="act0Seg1">
    <visual>
      <origin rpy="0 0 0" xyz="0 0 0.25" />
      <geometry>
        <box size="0.5 0.5 0.5" />
      </geometry>
      <material name="blue">
        <color rgba="0.3 0.0 1 1.0" />
      </material>
    </visual>
    <collision>
      <origin rpy="0 0 0" xyz="0 0 0.25" />
      <geometry>
        <box size="0.5 0.5 0.5" />
      </geometry>
    </collision>
    <inertial>
      <mass value="0.058230501033959554" />
      <inertia ixx="1" ixy="0" ixz="0" iyy="1" iyz="0" izz="1" />
      <origin rpy="0 0 0" xyz="0 0 0.25" />
    </inertial>
  </link>
  <joint name="act0Seg0_to_act0Seg1_ax0" type="revolute">
    <parent link="act0Seg0" />
    <child link="act0Seg1" />
    <origin rpy="0 0 0" xyz="0 0 0.25" />
    <axis xyz="1 0 0" />
    <limit effort="100" lower="-2.5" upper="2.5" velocity="3" />
  </joint>
  <link name="act0Seg1helper_shape">
    <visual>
      <origin rpy="0 -1.5707963267948966 0" xyz="0 0 0.0" />
      <geometry>
        <cylinder length="0.5" radius="0.25" />
      </geometry>
      <material name="blue">
        <color rgba="0.3 0.0 1 1.0" />
      </material>
    </visual>
    <collision>
      <origin rpy="0 -1.5707963267948966 0" xyz="0 0 0.0" />
      <geometry>
        <cylinder length="0.5" radius="0.25" />
      </geometry>
    </collision>
    <inertial>
      <mass value="5.823050103395956e-05" />
      <inertia ixx="0.001" ixy="0.0" ixz="0.0" iyy="0.001" iyz="0.0" izz="0.001" />
      <origin rpy="0 -1.5707963267948966 0" xyz="0 0 0.0" />
    </inertial>
  </link>
  <joint name="act0Seg0_to_act0Seg1_ax0helper_shape" type="fixed">
    <parent link="act0Seg0" />
    <child link="act0Seg1helper_shape" />
    <origin rpy="0 0 0" xyz="0 0 0.25" />
    <axis xyz="1 0 0" />
  </joint>
  <link name="act0Seg2">
    <visual>
      <origin rpy="0 0 0" xyz="0 0 0.25" />
      <geometry>
        <box size="0.5 0.5 0.5" />
      </geometry>
      <material name="blue">
        <color rgba="0.3 0.0 1 1.0" />
      </material>
    </visual>
    <collision>
      <origin rpy="0 0 0" xyz="0 0 0.25" />
      <geometry>
        <box size="0.5 0.5 0.5" />
      </geometry>
    </collision>
    <inertial>
      <mass value="0.058230501033959554" />
      <inertia ixx="1" ixy="0" ixz="0" iyy="1" iyz="0" izz="1" />
      <origin rpy="0 0 0" xyz="0 0 0.25" />
    </inertial>
  </link>
  <joint name="act0Seg1_to_act0Seg2_ax1" type="revolute">
    <parent link="act0Seg1" />
    <child link="act0Seg2" />
    <origin rpy="0 0 0" xyz="0 0 0.5" />
    <axis xyz="0 1 0" />
    <limit effort="100" lower="-1" upper="1" velocity="3" />
  </joint>
  <link name="act0Seg2helper_shape">
    <visual>
      <origin rpy="-1.5707963267948966 0 0" xyz="0 0 0.0" />
      <geometry>
        <cylinder length="0.5" radius="0.25" />
      </geometry>
      <material name="blue">
        <color rgba="0.3 0.0 1 1.0" />
      </material>
    </visual>
    <collision>
      <origin rpy="-1.5707963267948966 0 0" xyz="0 0 0.0" />
      <geometry>
        <cylinder length="0.5" radius="0.25" />
      </geometry>
    </collision>
    <inertial>
      <mass value="5.823050103395956e-05" />
      <inertia ixx="0.001" ixy="0.0" ixz="0.0" iyy="0.001" iyz="0.0" izz="0.001" />
      <origin rpy="-1.5707963267948966 0 0" xyz="0 0 0.0" />
    </inertial>
  </link>
  <joint name="act0Seg1_to_act0Seg2_ax1helper_shape" type="fixed">
    <parent link="act0Seg1" />
    <child link="act0Seg2helper_shape" />
    <origin rpy="0 0 0" xyz="0 0 0.5" />
    <axis xyz="1 0 0" />
  </joint>
  <link name="act0Seg3">
    <visual>
      <origin rpy="0 0 0" xyz="0 0 0.25" />
      <geometry>
        <box size="0.5 0.5 0.5" />
      </geometry>
      <material name="blue">
        <color rgba="0.3 0.0 1 1.0" />
      </material>
    </visual>
    <collision>
      <origin rpy="0 0 0" xyz="0 0 0.25" />
      <geometry>
        <box size="0.5 0.5 0.5" />
      </geometry>
    </collision>
    <inertial>
      <mass value="0.058230501033959554" />
      <inertia ixx="1" ixy="0" ixz="0" iyy="1" iyz="0" izz="1" />
      <origin rpy="0 0 0" xyz="0 0 0.25" />
    </inertial>
  </link>
  <joint name="act0Seg2_to_act0Seg3_ax0" type="revolute">
    <parent link="act0Seg2" />
    <child link="act0Seg3" />
    <origin rpy="0 0 0" xyz="0 0 0.5" />
    <axis xyz="1 0 0" />
    <limit effort="100" lower="-2.5" upper="2.5" velocity="3" />
  </joint>
  <link name="act0Seg3helper_shape">
    <visual>
      <origin rpy="0 -1.5707963267948966 0" xyz="0 0 0.0" />
      <geometry>
        <cylinder length="0.5" radius="0.25" />
      </geometry>
      <material name="blue">
        <color rgba="0.3 0.0 1 1.0" />
      </material>
    </visual>
    <collision>
      <origin rpy="0 -1.5707963267948966 0" xyz="0 0 0.0" />
      <geometry>
        <cylinder length="0.5" radius="0.25" />
      </geometry>
    </collision>
    <inertial>
      <mass value="5.823050103395956e-05" />
      <inertia ixx="0.001" ixy="0.0" ixz="0.0" iyy="0.001" iyz="0.0" izz="0.001" />
      <origin rpy="0 -1.5707963267948966 0" xyz="0 0 0.0" />
    </inertial>
  </link>
  <joint name="act0Seg2_to_act0Seg3_ax0helper_shape" type="fixed">
    <parent link="act0Seg2" />
    <child link="act0Seg3helper_shape" />
    <origin rpy="0 0 0" xyz="0 0 0.5" />
    <axis xyz="1 0 0" />
  </joint>
  <link name="act0Seg4">
    <visual>
      <origin rpy="0 0 0" xyz="0 0 0.25" />
      <geometry>
        <box size="0.5 0.5 0.5" />
      </geometry>
      <material name="blue">
        <color rgba="0.3 0.0 1 1.0" />
      </material>
    </visual>
    <collision>
      <origin rpy="0 0 0" xyz="0 0 0.25" />
      <geometry>
        <box size="0.5 0.5 0.5" />
      </geometry>
    </collision>
    <inertial>
      <mass value="0.058230501033959554" />
      <inertia ixx="1" ixy="0" ixz="0" iyy="1" iyz="0" izz="1" />
      <origin rpy="0 0 0" xyz="0 0 0.25" />
    </inertial>
  </link>
  <joint name="act0Seg3_to_act0Seg4_ax1" type="revolute">
    <parent link="act0Seg3" />
    <child link="act0Seg4" />
    <origin rpy="0 0 0" xyz="0 0 0.5" />
    <axis xyz="0 1 0" />
    <limit effort="100" lower="-1" upper="1" velocity="3" />
  </joint>
  <link name="act0Seg4helper_shape">
    <visual>
      <origin rpy="-1.5707963267948966 0 0" xyz="0 0 0.0" />
      <geometry>
        <cylinder length="0.5" radius="0.25" />
      </geometry>
      <material name="blue">
        <color rgba="0.3 0.0 1 1.0" />
      </material>
    </visual>
    <collision>
      <origin rpy="-1.5707963267948966 0 0" xyz="0 0 0.0" />
      <geometry>
        <cylinder length="0.5" radius="0.25" />
      </geometry>
    </collision>
    <inertial>
      <mass value="5.823050103395956e-05" />
      <inertia ixx="0.001" ixy="0.0" ixz="0.0" iyy="0.001" iyz="0.0" izz="0.001" />
      <origin rpy="-1.5707963267948966 0 0" xyz="0 0 0.0" />
    </inertial>
  </link>
  <joint name="act0Seg3_to_act0Seg4_ax1helper_shape" type="fixed">
    <parent link="act0Seg3" />
    <child link="act0Seg4helper_shape" />
    <origin rpy="0 0 0" xyz="0 0 0.5" />
    <axis xyz="1 0 0" />
  </joint>
  <link name="act0Seg5">
    <visual>
      <origin rpy="0 0 0" xyz="0 0 0.25" />
      <geometry>
        <box size="0.5 0.5 0.5" />
      </geometry>
      <material name="blue">
        <color rgba="0.3 0.0 1 1.0" />
      </material>
    </visual>
    <collision>
      <origin rpy="0 0 0" xyz="0 0 0.25" />
      <geometry>
        <box size="0.5 0.5 0.5" />
      </geometry>
    </collision>
    <inertial>
      <mass value="0.058230501033959554" />
      <inertia ixx="1" ixy="0" ixz="0" iyy="1" iyz="0" izz="1" />
      <origin rpy="0 0 0" xyz="0 0 0.25" />
    </inertial>
  </link>
  <joint name="act0Seg4_to_act0Seg5_ax0" type="revolute">
    <parent link="act0Seg4" />
    <child link="act0Seg5" />
    <origin rpy="0 0 0" xyz="0 0 0.5" />
    <axis xyz="1 0 0" />
    <limit effort="100" lower="-2.5" upper="2.5" velocity="3" />
  </joint>
  <link name="act0Seg5helper_shape">
    <visual>
      <origin rpy="0 -1.5707963267948966 0" xyz="0 0 0.0" />
      <geometry>
        <cylinder length="0.5" radius="0.25" />
      </geometry>
      <material name="blue">
        <color rgba="0.3 0.0 1 1.0" />
      </material>
    </visual>
    <collision>
      <origin rpy="0 -1.5707963267948966 0" xyz="0 0 0.0" />
      <geometry>
        <cylinder length="0.5" radius="0.25" />
      </geometry>
    </collision>
    <inertial>
      <mass value="5.823050103395956e-05" />
      <inertia ixx="0.001" ixy="0.0" ixz="0.0" iyy="0.001" iyz="0.0" izz="0.001" />
      <origin rpy="0 -1.5707963267948966 0" xyz="0 0 0.0" />
    </inertial>
  </link>
  <joint name="act0Seg4_to_act0Seg5_ax0helper_shape" type="fixed">
    <parent link="act0Seg4" />
    <child link="act0Seg5helper_shape" />
    <origin rpy="0 0 0" xyz="0 0 0.5" />
    <axis xyz="1 0 0" />
  </joint>
  <link name="act0Seg6">
    <visual>
      <origin rpy="0 0 0" xyz="0 0 0.25" />
      <geometry>
        <box size="0.5 0.5 0.5" />
      </geometry>
      <material name="blue">
        <color rgba="0.3 0.0 1 1.0" />
      </material>
    </visual>
    <collision>
      <origin rpy="0 0 0" xyz="0 0 0.25" />
      <geometry>
        <box size="0.5 0.5 0.5" />
      </geometry>
    </collision>
    <inertial>
      <mass value="0.058230501033959554" />
      <inertia ixx="1" ixy="0" ixz="0" iyy="1" iyz="0" izz="1" />
      <origin rpy="0 0 0" xyz="0 0 0.25" />
    </inertial>
  </link>
  <joint name="act0Seg5_to_act0Seg6_ax1" type="revolute">
    <parent link="act0Seg5" />
    <child link="act0Seg6" />
    <origin rpy="0 0 0" xyz="0 0 0.5" />
    <axis xyz="0 1 0" />
    <limit effort="100" lower="-1" upper="1" velocity="3" />
  </joint>
  <link name="act0Seg6helper_shape">
    <visual>
      <origin rpy="-1.5707963267948966 0 0" xyz="0 0 0.0" />
      <geometry>
        <cylinder length="0.5" radius="0.25" />
      </geometry>
      <material name="blue">
        <color rgba="0.3 0.0 1 1.0" />
      </material>
    </visual>
    <collision>
      <origin rpy="-1.5707963267948966 0 0" xyz="0 0 0.0" />
      <geometry>
        <cylinder length="0.5" radius="0.25" />
      </geometry>
    </collision>
    <inertial>
      <mass value="5.823050103395956e-05" />
      <inertia ixx="0.001" ixy="0.0" ixz="0.0" iyy="0.001" iyz="0.0" izz="0.001" />
      <origin rpy="-1.5707963267948966 0 0" xyz="0 0 0.0" />
    </inertial>
  </link>
  <joint name="act0Seg5_to_act0Seg6_ax1helper_shape" type="fixed">
    <parent link="act0Seg5" />
    <child link="act0Seg6helper_shape" />
    <origin rpy="0 0 0" xyz="0 0 0.5" />
    <axis xyz="1 0 0" />
  </joint>
  <link name="act0Seg7">
    <visual>
      <origin rpy="0 0 0" xyz="0 0 0.25" />
      <geometry>
        <box size="0.5 0.5 0.5" />
      </geometry>
      <material name="blue">
        <color rgba="0.3 0.0 1 1.0" />
      </material>
    </visual>
    <collision>
      <origin rpy="0 0 0" xyz="0 0 0.25" />
      <geometry>
        <box size="0.5 0.5 0.5" />
      </geometry>
    </collision>
    <inertial>
      <mass value="0.058230501033959554" />
      <inertia ixx="1" ixy="0" ixz="0" iyy="1" iyz="0" izz="1" />
      <origin rpy="0 0 0" xyz="0 0 0.25" />
    </inertial>
  </link>
  <joint name="act0Seg6_to_act0Seg7_ax0" type="revolute">
    <parent link="act0Seg6" />
    <child link="act0Seg7" />
    <origin rpy="0 0 0" xyz="0 0 0.5" />
    <axis xyz="1 0 0" />
    <limit effort="100" lower="-2.5" upper="2.5" velocity="3" />
  </joint>
  <link name="act0Seg7helper_shape">
    <visual>
      <origin rpy="0 -1.5707963267948966 0" xyz="0 0 0.0" />
      <geometry>
        <cylinder length="0.5" radius="0.25" />
      </geometry>
      <material name="blue">
        <color rgba="0.3 0.0 1 1.0" />
      </material>
    </visual>
    <collision>
      <origin rpy="0 -1.5707963267948966 0" xyz="0 0 0.0" />
      <geometry>
        <cylinder length="0.5" radius="0.25" />
      </geometry>
    </collision>
    <inertial>
      <mass value="5.823050103395956e-05" />
      <inertia ixx="0.001" ixy="0.0" ixz="0.0" iyy="0.001" iyz="0.0" izz="0.001" />
      <origin rpy="0 -1.5707963267948966 0" xyz="0 0 0.0" />
    </inertial>
  </link>
  <joint name="act0Seg6_to_act0Seg7_ax0helper_shape" type="fixed">
    <parent link="act0Seg6" />
    <child link="act0Seg7helper_shape" />
    <origin rpy="0 0 0" xyz="0 0 0.5" />
    <axis xyz="1 0 0" />
  </joint>
  <link name="act0Seg8">
    <visual>
      <origin rpy="0 0 0" xyz="0 0 0.25" />
      <geometry>
        <box size="0.5 0.5 0.5" />
      </geometry>
      <material name="blue">
        <color rgba="0.3 0.0 1 1.0" />
      </material>
    </visual>
    <collision>
      <origin rpy="0 0 0" xyz="0 0 0.25" />
      <geometry>
        <box size="0.5 0.5 0.5" />
      </geometry>
    </collision>
    <inertial>
      <mass value="0.058230501033959554" />
      <inertia ixx="1" ixy="0" ixz="0" iyy="1" iyz="0" izz="1" />
      <origin rpy="0 0 0" xyz="0 0 0.25" />
    </inertial>
  </link>
  <joint name="act0Seg7_to_act0Seg8_ax1" type="revolute">
    <parent link="act0Seg7" />
    <child link="act0Seg8" />
    <origin rpy="0 0 0" xyz="0 0 0.5" />
    <axis xyz="0 1 0" />
    <limit effort="100" lower="-1" upper="1" velocity="3" />
  </joint>
  <link name="act0Seg8helper_shape">
    <visual>
      <origin rpy="-1.5707963267948966 0 0" xyz="0 0 0.0" />
      <geometry>
        <cylinder length="0.5" radius="0.25" />
      </geometry>
      <material name="blue">
        <color rgba="0.3 0.0 1 1.0" />
      </material>
    </visual>
    <collision>
      <origin rpy="-1.5707963267948966 0 0" xyz="0 0 0.0" />
      <geometry>
        <cylinder length="0.5" radius="0.25" />
      </geometry>
    </collision>
    <inertial>
      <mass value="5.823050103395956e-05" />
      <inertia ixx="0.001" ixy="0.0" ixz="0.0" iyy="0.001" iyz="0.0" izz="0.001" />
      <origin rpy="-1.5707963267948966 0 0" xyz="0 0 0.0" />
    </inertial>
  </link>
  <joint name="act0Seg7_to_act0Seg8_ax1helper_shape" type="fixed">
    <parent link="act0Seg7" />
    <child link="act0Seg8helper_shape" />
    <origin rpy="0 0 0" xyz="0 0 0.5" />
    <axis xyz="1 0 0" />
  </joint>
  <link name="act0Seg9">
    <visual>
      <origin rpy="0 0 0" xyz="0 0 0.25" />
      <geometry>
        <box size="0.5 0.5 0.5" />
      </geometry>
      <material name="blue">
        <color rgba="0.3 0.0 1 1.0" />
      </material>
    </visual>
    <collision>
      <origin rpy="0 0 0" xyz="0 0 0.25" />
      <geometry>
        <box size="0.5 0.5 0.5" />
      </geometry>
    </collision>
    <inertial>
      <mass value="0.058230501033959554" />
      <inertia ixx="1" ixy="0" ixz="0" iyy="1" iyz="0" izz="1" />
      <origin rpy="0 0 0" xyz="0 0 0.25" />
    </inertial>
  </link>
  <joint name="act0Seg8_to_act0Seg9_ax0" type="revolute">
    <parent link="act0Seg8" />
    <child link="act0Seg9" />
    <origin rpy="0 0 0" xyz="0 0 0.5" />
    <axis xyz="1 0 0" />
    <limit effort="100" lower="-2.5" upper="2.5" velocity="3" />
  </joint>
  <link name="act0Seg9helper_shape">
    <visual>
      <origin rpy="0 -1.5707963267948966 0" xyz="0 0 0.0" />
      <geometry>
        <cylinder length="0.5" radius="0.25" />
      </geometry>
      <material name="blue">
        <color rgba="0.3 0.0 1 1.0" />
      </material>
    </visual>
    <collision>
      <origin rpy="0 -1.5707963267948966 0" xyz="0 0 0.0" />
      <geometry>
        <cylinder length="0.5" radius="0.25" />
      </geometry>
    </collision>
    <inertial>
      <mass value="5.823050103395956e-05" />
      <inertia ixx="0.001" ixy="0.0" ixz="0.0" iyy="0.001" iyz="0.0" izz="0.001" />
      <origin rpy="0 -1.5707963267948966 0" xyz="0 0 0.0" />
    </inertial>
  </link>
  <joint name="act0Seg8_to_act0Seg9_ax0helper_shape" type="fixed">
    <parent link="act0Seg8" />
    <child link="act0Seg9helper_shape" />
    <origin rpy="0 0 0" xyz="0 0 0.5" />
    <axis xyz="1 0 0" />
  </joint>
  <link name="act0Seg10">
    <visual>
      <origin rpy="0 0 0" xyz="0 0 0.25" />
      <geometry>
        <box size="0.5 0.5 0.5" />
      </geometry>
      <material name="blue">
        <color rgba="0.3 0.0 1 1.0" />
      </material>
    </visual>
    <collision>
      <origin rpy="0 0 0" xyz="0 0 0.25" />
      <geometry>
        <box size="0.5 0.5 0.5" />
      </geometry>
    </collision>
    <inertial>
      <mass value="0.058230501033959554" />
      <inertia ixx="1" ixy="0" ixz="0" iyy="1" iyz="0" izz="1" />
      <origin rpy="0 0 0" xyz="0 0 0.25" />
    </inertial>
  </link>
  <joint name="act0Seg9_to_act0Seg10_ax1" type="revolute">
    <parent link="act0Seg9" />
    <child link="act0Seg10" />
    <origin rpy="0 0 0" xyz="0 0 0.5" />
    <axis xyz="0 1 0" />
    <limit effort="100" lower="-1" upper="1" velocity="3" />
  </joint>
  <link name="act0Seg10helper_shape">
    <visual>
      <origin rpy="-1.5707963267948966 0 0" xyz="0 0 0.0" />
      <geometry>
        <cylinder length="0.5" radius="0.25" />
      </geometry>
      <material name="blue">
        <color rgba="0.3 0.0 1 1.0" />
      </material>
    </visual>
    <collision>
      <origin rpy="-1.5707963267948966 0 0" xyz="0 0 0.0" />
      <geometry>
        <cylinder length="0.5" radius="0.25" />
      </geometry>
    </collision>
    <inertial>
      <mass value="5.823050103395956e-05" />
      <inertia ixx="0.001" ixy="0.0" ixz="0.0" iyy="0.001" iyz="0.0" izz="0.001" />
      <origin rpy="-1.5707963267948966 0 0" xyz="0 0 0.0" />
    </inertial>
  </link>
  <joint name="act0Seg9_to_act0Seg10_ax1helper_shape" type="fixed">
    <parent link="act0Seg9" />
    <child link="act0Seg10helper_shape" />
    <origin rpy="0 0 0" xyz="0 0 0.5" />
    <axis xyz="1 0 0" />
  </joint>
  <link name="act0Seg11">
    <visual>
      <origin rpy="0 0 0" xyz="0 0 0.25" />
      <geometry>
        <box size="0.5 0.5 0.5" />
      </geometry>
      <material name="blue">
        <color rgba="0.3 0.0 1 1.0" />
      </material>
    </visual>
    <collision>
      <origin rpy="0 0 0" xyz="0 0 0.25" />
      <geometry>
        <box size="0.5 0.5 0.5" />
      </geometry>
    </collision>
    <inertial>
      <mass value="0.058230501033959554" />
      <inertia ixx="1" ixy="0" ixz="0" iyy="1" iyz="0" izz="1" />
      <origin rpy="0 0 0" xyz="0 0 0.25" />
    </inertial>
  </link>
  <joint name="act0Seg10_to_act0Seg11_ax0" type="revolute">
    <parent link="act0Seg10" />
    <child link="act0Seg11" />
    <origin rpy="0 0 0" xyz="0 0 0.5" />
    <axis xyz="1 0 0" />
    <limit effort="100" lower="-2.5" upper="2.5" velocity="3" />
  </joint>
  <link name="act0Seg11helper_shape">
    <visual>
      <origin rpy="0 -1.5707963267948966 0" xyz="0 0 0.0" />
      <geometry>
        <cylinder length="0.5" radius="0.25" />
      </geometry>
      <material name="blue">
        <color rgba="0.3 0.0 1 1.0" />
      </material>
    </visual>
    <collision>
      <origin rpy="0 -1.5707963267948966 0" xyz="0 0 0.0" />
      <geometry>
        <cylinder length="0.5" radius="0.25" />
      </geometry>
    </collision>
    <inertial>
      <mass value="5.823050103395956e-05" />
      <inertia ixx="0.001" ixy="0.0" ixz="0.0" iyy="0.001" iyz="0.0" izz="0.001" />
      <origin rpy="0 -1.5707963267948966 0" xyz="0 0 0.0" />
    </inertial>
  </link>
  <joint name="act0Seg10_to_act0Seg11_ax0helper_shape" type="fixed">
    <parent link="act0Seg10" />
    <child link="act0Seg11helper_shape" />
    <origin rpy="0 0 0" xyz="0 0 0.5" />
    <axis xyz="1 0 0" />
  </joint>
  <link name="act0Seg12">
    <visual>
      <origin rpy="0 0 0" xyz="0 0 0.25" />
      <geometry>
        <box size="0.5 0.5 0.5" />
      </geometry>
      <material name="blue">
        <color rgba="0.3 0.0 1 1.0" />
      </material>
    </visual>
    <collision>
      <origin rpy="0 0 0" xyz="0 0 0.25" />
      <geometry>
        <box size="0.5 0.5 0.5" />
      </geometry>
    </collision>
    <inertial>
      <mass value="0.058230501033959554" />
      <inertia ixx="1" ixy="0" ixz="0" iyy="1" iyz="0" izz="1" />
      <origin rpy="0 0 0" xyz="0 0 0.25" />
    </inertial>
  </link>
  <joint name="act0Seg11_to_act0Seg12_ax1" type="revolute">
    <parent link="act0Seg11" />
    <child link="act0Seg12" />
    <origin rpy="0 0 0" xyz="0 0 0.5" />
    <axis xyz="0 1 0" />
    <limit effort="100" lower="-1" upper="1" velocity="3" />
  </joint>
  <link name="act0Seg12helper_shape">
    <visual>
      <origin rpy="-1.5707963267948966 0 0" xyz="0 0 0.0" />
      <geometry>
        <cylinder length="0.5" radius="0.25" />
      </geometry>
      <material name="blue">
        <color rgba="0.3 0.0 1 1.0" />
      </material>
    </visual>
    <collision>
      <origin rpy="-1.5707963267948966 0 0" xyz="0 0 0.0" />
      <geometry>
        <cylinder length="0.5" radius="0.25" />
      </geometry>
    </collision>
    <inertial>
      <mass value="5.823050103395956e-05" />
      <inertia ixx="0.001" ixy="0.0" ixz="0.0" iyy="0.001" iyz="0.0" izz="0.001" />
      <origin rpy="-1.5707963267948966 0 0" xyz="0 0 0.0" />
    </inertial>
  </link>
  <joint name="act0Seg11_to_act0Seg12_ax1helper_shape" type="fixed">
    <parent link="act0Seg11" />
    <child link="act0Seg12helper_shape" />
    <origin rpy="0 0 0" xyz="0 0 0.5" />
    <axis xyz="1 0 0" />
  </joint>
  <link name="act0Seg13">
    <visual>
      <origin rpy="0 0 0" xyz="0 0 0.25" />
      <geometry>
        <box size="0.5 0.5 0.5" />
      </geometry>
      <material name="blue">
        <color rgba="0.3 0.0 1 1.0" />
      </material>
    </visual>
    <collision>
      <origin rpy="0 0 0" xyz="0 0 0.25" />
      <geometry>
        <box size="0.5 0.5 0.5" />
      </geometry>
    </collision>
    <inertial>
      <mass value="0.058230501033959554" />
      <inertia ixx="1" ixy="0" ixz="0" iyy="1" iyz="0" izz="1" />
      <origin rpy="0 0 0" xyz="0 0 0.25" />
    </inertial>
  </link>
  <joint name="act0Seg12_to_act0Seg13_ax0" type="revolute">
    <parent link="act0Seg12" />
    <child link="act0Seg13" />
    <origin rpy="0 0 0" xyz="0 0 0.5" />
    <axis xyz="1 0 0" />
    <limit effort="100" lower="-2.5" upper="2.5" velocity="3" />
  </joint>
  <link name="act0Seg13helper_shape">
    <visual>
      <origin rpy="0 -1.5707963267948966 0" xyz="0 0 0.0" />
      <geometry>
        <cylinder length="0.5" radius="0.25" />
      </geometry>
      <material name="blue">
        <color rgba="0.3 0.0 1 1.0" />
      </material>
    </visual>
    <collision>
      <origin rpy="0 -1.5707963267948966 0" xyz="0 0 0.0" />
      <geometry>
        <cylinder length="0.5" radius="0.25" />
      </geometry>
    </collision>
    <inertial>
      <mass value="5.823050103395956e-05" />
      <inertia ixx="0.001" ixy="0.0" ixz="0.0" iyy="0.001" iyz="0.0" izz="0.001" />
      <origin rpy="0 -1.5707963267948966 0" xyz="0 0 0.0" />
    </inertial>
  </link>
  <joint name="act0Seg12_to_act0Seg13_ax0helper_shape" type="fixed">
    <parent link="act0Seg12" />
    <child link="act0Seg13helper_shape" />
    <origin rpy="0 0 0" xyz="0 0 0.5" />
    <axis xyz="1 0 0" />
  </joint>
  <link name="act0Seg14">
    <visual>
      <origin rpy="0 0 0" xyz="0 0 0.125" />
      <geometry>
        <box size="0.5 0.5 0.25" />
      </geometry>
      <material name="blue">
        <color rgba="0.3 0.0 1 1.0" />
      </material>
    </visual>
    <collision>
      <origin rpy="0 0 0" xyz="0 0 0.125" />
      <geometry>
        <box size="0.5 0.5 0.25" />
      </geometry>
    </collision>
    <inertial>
      <mass value="0.058230501033959554" />
      <inertia ixx="1" ixy="0" ixz="0" iyy="1" iyz="0" izz="1" />
      <origin rpy="0 0 0" xyz="0 0 0.125" />
    </inertial>
  </link>
  <joint name="act0Seg13_to_act0Seg14_ax1" type="revolute">
    <parent link="act0Seg13" />
    <child link="act0Seg14" />
    <origin rpy="0 0 0" xyz="0 0 0.5" />
    <axis xyz="0 1 0" />
    <limit effort="100" lower="-1" upper="1" velocity="3" />
  </joint>
  <link name="act0Seg14helper_shape">
    <visual>
      <origin rpy="-1.5707963267948966 0 0" xyz="0 0 0.0" />
      <geometry>
        <cylinder length="0.5" radius="0.25" />
      </geometry>
      <material name="blue">
        <color rgba="0.3 0.0 1 1.0" />
      </material>
    </visual>
    <collision>
      <origin rpy="-1.5707963267948966 0 0" xyz="0 0 0.0" />
      <geometry>
        <cylinder length="0.5" radius="0.25" />
      </geometry>
    </collision>
    <inertial>
      <mass value="5.823050103395956e-05" />
      <inertia ixx="0.001" ixy="0.0" ixz="0.0" iyy="0.001" iyz="0.0" izz="0.001" />
      <origin rpy="-1.5707963267948966 0 0" xyz="0 0 0.0" />
    </inertial>
  </link>
  <joint name="act0Seg13_to_act0Seg14_ax1helper_shape" type="fixed">
    <parent link="act0Seg13" />
    <child link="act0Seg14helper_shape" />
    <origin rpy="0 0 0" xyz="0 0 0.5" />
    <axis xyz="1 0 0" />
  </joint>
  <link name="act1Seg0">
    <visual>
      <origin rpy="0 0 0" xyz="0 0 0.125" />
      <geometry>
        <box size="0.5 0.5 0.25" />
      </geometry>
      <material name="blue">
        <color rgba="0.3 0.0 1 1.0" />
      </material>
    </visual>
    <collision>
      <origin rpy="0 0 0" xyz="0 0 0.125" />
      <geometry>
        <box size="0.5 0.5 0.25" />
      </geometry>
    </collision>
    <inertial>
      <mass value="0.055467879993584955" />
      <inertia ixx="1" ixy="0" ixz="0" iyy="1" iyz="0" izz="1" />
      <origin rpy="0 0 0" xyz="0 0 0.125" />
    </inertial>
  </link>
  <joint name="act0Seg14_to_act1Seg0_ax1" type="fixed">
    <parent link="act0Seg14" />
    <child link="act1Seg0" />
    <origin rpy="0 0 0" xyz="0 0 0.25" />
    <axis xyz="0 1 0" />
    <limit effort="100" lower="-3.141592" upper="3.141592" velocity="3" />
  </joint>
  <link name="act1Seg1">
    <visual>
      <origin rpy="0 0 0" xyz="0 0 0.25" />
      <geometry>
        <box size="0.5 0.5 0.5" />
      </geometry>
      <material name="blue">
        <color rgba="0.3 0.0 1 1.0" />
      </material>
    </visual>
    <collision>
      <origin rpy="0 0 0" xyz="0 0 0.25" />
      <geometry>
        <box size="0.5 0.5 0.5" />
      </geometry>
    </collision>
    <inertial>
      <mass value="0.055467879993584955" />
      <inertia ixx="1" ixy="0" ixz="0" iyy="1" iyz="0" izz="1" />
      <origin rpy="0 0 0" xyz="0 0 0.25" />
    </inertial>
  </link>
  <joint name="act1Seg0_to_act1Seg1_ax0" type="revolute">
    <parent link="act1Seg0" />
    <child link="act1Seg1" />
    <origin rpy="0 0 0" xyz="0 0 0.25" />
    <axis xyz="1 0 0" />
    <limit effort="100" lower="-1" upper="1" velocity="3" />
  </joint>
  <link name="act1Seg1helper_shape">
    <visual>
      <origin rpy="0 -1.5707963267948966 0" xyz="0 0 0.0" />
      <geometry>
        <cylinder length="0.5" radius="0.25" />
      </geometry>
      <material name="blue">
        <color rgba="0.3 0.0 1 1.0" />
      </material>
    </visual>
    <collision>
      <origin rpy="0 -1.5707963267948966 0" xyz="0 0 0.0" />
      <geometry>
        <cylinder length="0.5" radius="0.25" />
      </geometry>
    </collision>
    <inertial>
      <mass value="5.5467879993584955e-05" />
      <inertia ixx="0.001" ixy="0.0" ixz="0.0" iyy="0.001" iyz="0.0" izz="0.001" />
      <origin rpy="0 -1.5707963267948966 0" xyz="0 0 0.0" />
    </inertial>
  </link>
  <joint name="act1Seg0_to_act1Seg1_ax0helper_shape" type="fixed">
    <parent link="act1Seg0" />
    <child link="act1Seg1helper_shape" />
    <origin rpy="0 0 0" xyz="0 0 0.25" />
    <axis xyz="1 0 0" />
  </joint>
  <link name="act1Seg2">
    <visual>
      <origin rpy="0 0 0" xyz="0 0 0.25" />
      <geometry>
        <box size="0.5 0.5 0.5" />
      </geometry>
      <material name="blue">
        <color rgba="0.3 0.0 1 1.0" />
      </material>
    </visual>
    <collision>
      <origin rpy="0 0 0" xyz="0 0 0.25" />
      <geometry>
        <box size="0.5 0.5 0.5" />
      </geometry>
    </collision>
    <inertial>
      <mass value="0.055467879993584955" />
      <inertia ixx="1" ixy="0" ixz="0" iyy="1" iyz="0" izz="1" />
      <origin rpy="0 0 0" xyz="0 0 0.25" />
    </inertial>
  </link>
  <joint name="act1Seg1_to_act1Seg2_ax1" type="revolute">
    <parent link="act1Seg1" />
    <child link="act1Seg2" />
    <origin rpy="0 0 0" xyz="0 0 0.5" />
    <axis xyz="0 1 0" />
    <limit effort="100" lower="-3.141592" upper="3.141592" velocity="3" />
  </joint>
  <link name="act1Seg2helper_shape">
    <visual>
      <origin rpy="-1.5707963267948966 0 0" xyz="0 0 0.0" />
      <geometry>
        <cylinder length="0.5" radius="0.25" />
      </geometry>
      <material name="blue">
        <color rgba="0.3 0.0 1 1.0" />
      </material>
    </visual>
    <collision>
      <origin rpy="-1.5707963267948966 0 0" xyz="0 0 0.0" />
      <geometry>
        <cylinder length="0.5" radius="0.25" />
      </geometry>
    </collision>
    <inertial>
      <mass value="5.5467879993584955e-05" />
      <inertia ixx="0.001" ixy="0.0" ixz="0.0" iyy="0.001" iyz="0.0" izz="0.001" />
      <origin rpy="-1.5707963267948966 0 0" xyz="0 0 0.0" />
    </inertial>
  </link>
  <joint name="act1Seg1_to_act1Seg2_ax1helper_shape" type="fixed">
    <parent link="act1Seg1" />
    <child link="act1Seg2helper_shape" />
    <origin rpy="0 0 0" xyz="0 0 0.5" />
    <axis xyz="1 0 0" />
  </joint>
  <link name="act1Seg3">
    <visual>
      <origin rpy="0 0 0" xyz="0 0 0.25" />
      <geometry>
        <box size="0.5 0.5 0.5" />
      </geometry>
      <material name="blue">
        <color rgba="0.3 0.0 1 1.0" />
      </material>
    </visual>
    <collision>
      <origin rpy="0 0 0" xyz="0 0 0.25" />
      <geometry>
        <box size="0.5 0.5 0.5" />
      </geometry>
    </collision>
    <inertial>
      <mass value="0.055467879993584955" />
      <inertia ixx="1" ixy="0" ixz="0" iyy="1" iyz="0" izz="1" />
      <origin rpy="0 0 0" xyz="0 0 0.25" />
    </inertial>
  </link>
  <joint name="act1Seg2_to_act1Seg3_ax0" type="revolute">
    <parent link="act1Seg2" />
    <child link="act1Seg3" />
    <origin rpy="0 0 0" xyz="0 0 0.5" />
    <axis xyz="1 0 0" />
    <limit effort="100" lower="-1" upper="1" velocity="3" />
  </joint>
  <link name="act1Seg3helper_shape">
    <visual>
      <origin rpy="0 -1.5707963267948966 0" xyz="0 0 0.0" />
      <geometry>
        <cylinder length="0.5" radius="0.25" />
      </geometry>
      <material name="blue">
        <color rgba="0.3 0.0 1 1.0" />
      </material>
    </visual>
    <collision>
      <origin rpy="0 -1.5707963267948966 0" xyz="0 0 0.0" />
      <geometry>
        <cylinder length="0.5" radius="0.25" />
      </geometry>
    </collision>
    <inertial>
      <mass value="5.5467879993584955e-05" />
      <inertia ixx="0.001" ixy="0.0" ixz="0.0" iyy="0.001" iyz="0.0" izz="0.001" />
      <origin rpy="0 -1.5707963267948966 0" xyz="0 0 0.0" />
    </inertial>
  </link>
  <joint name="act1Seg2_to_act1Seg3_ax0helper_shape" type="fixed">
    <parent link="act1Seg2" />
    <child link="act1Seg3helper_shape" />
    <origin rpy="0 0 0" xyz="0 0 0.5" />
    <axis xyz="1 0 0" />
  </joint>
  <link name="act1Seg4">
    <visual>
      <origin rpy="0 0 0" xyz="0 0 0.25" />
      <geometry>
        <box size="0.5 0.5 0.5" />
      </geometry>
      <material name="blue">
        <color rgba="0.3 0.0 1 1.0" />
      </material>
    </visual>
    <collision>
      <origin rpy="0 0 0" xyz="0 0 0.25" />
      <geometry>
        <box size="0.5 0.5 0.5" />
      </geometry>
    </collision>
    <inertial>
      <mass value="0.055467879993584955" />
      <inertia ixx="1" ixy="0" ixz="0" iyy="1" iyz="0" izz="1" />
      <origin rpy="0 0 0" xyz="0 0 0.25" />
    </inertial>
  </link>
  <joint name="act1Seg3_to_act1Seg4_ax1" type="revolute">
    <parent link="act1Seg3" />
    <child link="act1Seg4" />
    <origin rpy="0 0 0" xyz="0 0 0.5" />
    <axis xyz="0 1 0" />
    <limit effort="100" lower="-3.141592" upper="3.141592" velocity="3" />
  </joint>
  <link name="act1Seg4helper_shape">
    <visual>
      <origin rpy="-1.5707963267948966 0 0" xyz="0 0 0.0" />
      <geometry>
        <cylinder length="0.5" radius="0.25" />
      </geometry>
      <material name="blue">
        <color rgba="0.3 0.0 1 1.0" />
      </material>
    </visual>
    <collision>
      <origin rpy="-1.5707963267948966 0 0" xyz="0 0 0.0" />
      <geometry>
        <cylinder length="0.5" radius="0.25" />
      </geometry>
    </collision>
    <inertial>
      <mass value="5.5467879993584955e-05" />
      <inertia ixx="0.001" ixy="0.0" ixz="0.0" iyy="0.001" iyz="0.0" izz="0.001" />
      <origin rpy="-1.5707963267948966 0 0" xyz="0 0 0.0" />
    </inertial>
  </link>
  <joint name="act1Seg3_to_act1Seg4_ax1helper_shape" type="fixed">
    <parent link="act1Seg3" />
    <child link="act1Seg4helper_shape" />
    <origin rpy="0 0 0" xyz="0 0 0.5" />
    <axis xyz="1 0 0" />
  </joint>
  <link name="act1Seg5">
    <visual>
      <origin rpy="0 0 0" xyz="0 0 0.25" />
      <geometry>
        <box size="0.5 0.5 0.5" />
      </geometry>
      <material name="blue">
        <color rgba="0.3 0.0 1 1.0" />
      </material>
    </visual>
    <collision>
      <origin rpy="0 0 0" xyz="0 0 0.25" />
      <geometry>
        <box size="0.5 0.5 0.5" />
      </geometry>
    </collision>
    <inertial>
      <mass value="0.055467879993584955" />
      <inertia ixx="1" ixy="0" ixz="0" iyy="1" iyz="0" izz="1" />
      <origin rpy="0 0 0" xyz="0 0 0.25" />
    </inertial>
  </link>
  <joint name="act1Seg4_to_act1Seg5_ax0" type="revolute">
    <parent link="act1Seg4" />
    <child link="act1Seg5" />
    <origin rpy="0 0 0" xyz="0 0 0.5" />
    <axis xyz="1 0 0" />
    <limit effort="100" lower="-1" upper="1" velocity="3" />
  </joint>
  <link name="act1Seg5helper_shape">
    <visual>
      <origin rpy="0 -1.5707963267948966 0" xyz="0 0 0.0" />
      <geometry>
        <cylinder length="0.5" radius="0.25" />
      </geometry>
      <material name="blue">
        <color rgba="0.3 0.0 1 1.0" />
      </material>
    </visual>
    <collision>
      <origin rpy="0 -1.5707963267948966 0" xyz="0 0 0.0" />
      <geometry>
        <cylinder length="0.5" radius="0.25" />
      </geometry>
    </collision>
    <inertial>
      <mass value="5.5467879993584955e-05" />
      <inertia ixx="0.001" ixy="0.0" ixz="0.0" iyy="0.001" iyz="0.0" izz="0.001" />
      <origin rpy="0 -1.5707963267948966 0" xyz="0 0 0.0" />
    </inertial>
  </link>
  <joint name="act1Seg4_to_act1Seg5_ax0helper_shape" type="fixed">
    <parent link="act1Seg4" />
    <child link="act1Seg5helper_shape" />
    <origin rpy="0 0 0" xyz="0 0 0.5" />
    <axis xyz="1 0 0" />
  </joint>
  <link name="act1Seg6">
    <visual>
      <origin rpy="0 0 0" xyz="0 0 0.25" />
      <geometry>
        <box size="0.5 0.5 0.5" />
      </geometry>
      <material name="blue">
        <color rgba="0.3 0.0 1 1.0" />
      </material>
    </visual>
    <collision>
      <origin rpy="0 0 0" xyz="0 0 0.25" />
      <geometry>
        <box size="0.5 0.5 0.5" />
      </geometry>
    </collision>
    <inertial>
      <mass value="0.055467879993584955" />
      <inertia ixx="1" ixy="0" ixz="0" iyy="1" iyz="0" izz="1" />
      <origin rpy="0 0 0" xyz="0 0 0.25" />
    </inertial>
  </link>
  <joint name="act1Seg5_to_act1Seg6_ax1" type="revolute">
    <parent link="act1Seg5" />
    <child link="act1Seg6" />
    <origin rpy="0 0 0" xyz="0 0 0.5" />
    <axis xyz="0 1 0" />
    <limit effort="100" lower="-3.141592" upper="3.141592" velocity="3" />
  </joint>
  <link name="act1Seg6helper_shape">
    <visual>
      <origin rpy="-1.5707963267948966 0 0" xyz="0 0 0.0" />
      <geometry>
        <cylinder length="0.5" radius="0.25" />
      </geometry>
      <material name="blue">
        <color rgba="0.3 0.0 1 1.0" />
      </material>
    </visual>
    <collision>
      <origin rpy="-1.5707963267948966 0 0" xyz="0 0 0.0" />
      <geometry>
        <cylinder length="0.5" radius="0.25" />
      </geometry>
    </collision>
    <inertial>
      <mass value="5.5467879993584955e-05" />
      <inertia ixx="0.001" ixy="0.0" ixz="0.0" iyy="0.001" iyz="0.0" izz="0.001" />
      <origin rpy="-1.5707963267948966 0 0" xyz="0 0 0.0" />
    </inertial>
  </link>
  <joint name="act1Seg5_to_act1Seg6_ax1helper_shape" type="fixed">
    <parent link="act1Seg5" />
    <child link="act1Seg6helper_shape" />
    <origin rpy="0 0 0" xyz="0 0 0.5" />
    <axis xyz="1 0 0" />
  </joint>
  <link name="act1Seg7">
    <visual>
      <origin rpy="0 0 0" xyz="0 0 0.25" />
      <geometry>
        <box size="0.5 0.5 0.5" />
      </geometry>
      <material name="blue">
        <color rgba="0.3 0.0 1 1.0" />
      </material>
    </visual>
    <collision>
      <origin rpy="0 0 0" xyz="0 0 0.25" />
      <geometry>
        <box size="0.5 0.5 0.5" />
      </geometry>
    </collision>
    <inertial>
      <mass value="0.055467879993584955" />
      <inertia ixx="1" ixy="0" ixz="0" iyy="1" iyz="0" izz="1" />
      <origin rpy="0 0 0" xyz="0 0 0.25" />
    </inertial>
  </link>
  <joint name="act1Seg6_to_act1Seg7_ax0" type="revolute">
    <parent link="act1Seg6" />
    <child link="act1Seg7" />
    <origin rpy="0 0 0" xyz="0 0 0.5" />
    <axis xyz="1 0 0" />
    <limit effort="100" lower="-1" upper="1" velocity="3" />
  </joint>
  <link name="act1Seg7helper_shape">
    <visual>
      <origin rpy="0 -1.5707963267948966 0" xyz="0 0 0.0" />
      <geometry>
        <cylinder length="0.5" radius="0.25" />
      </geometry>
      <material name="blue">
        <color rgba="0.3 0.0 1 1.0" />
      </material>
    </visual>
    <collision>
      <origin rpy="0 -1.5707963267948966 0" xyz="0 0 0.0" />
      <geometry>
        <cylinder length="0.5" radius="0.25" />
      </geometry>
    </collision>
    <inertial>
      <mass value="5.5467879993584955e-05" />
      <inertia ixx="0.001" ixy="0.0" ixz="0.0" iyy="0.001" iyz="0.0" izz="0.001" />
      <origin rpy="0 -1.5707963267948966 0" xyz="0 0 0.0" />
    </inertial>
  </link>
  <joint name="act1Seg6_to_act1Seg7_ax0helper_shape" type="fixed">
    <parent link="act1Seg6" />
    <child link="act1Seg7helper_shape" />
    <origin rpy="0 0 0" xyz="0 0 0.5" />
    <axis xyz="1 0 0" />
  </joint>
  <link name="act1Seg8">
    <visual>
      <origin rpy="0 0 0" xyz="0 0 0.25" />
      <geometry>
        <box size="0.5 0.5 0.5" />
      </geometry>
      <material name="blue">
        <color rgba="0.3 0.0 1 1.0" />
      </material>
    </visual>
    <collision>
      <origin rpy="0 0 0" xyz="0 0 0.25" />
      <geometry>
        <box size="0.5 0.5 0.5" />
      </geometry>
    </collision>
    <inertial>
      <mass value="0.055467879993584955" />
      <inertia ixx="1" ixy="0" ixz="0" iyy="1" iyz="0" izz="1" />
      <origin rpy="0 0 0" xyz="0 0 0.25" />
    </inertial>
  </link>
  <joint name="act1Seg7_to_act1Seg8_ax1" type="revolute">
    <parent link="act1Seg7" />
    <child link="act1Seg8" />
    <origin rpy="0 0 0" xyz="0 0 0.5" />
    <axis xyz="0 1 0" />
    <limit effort="100" lower="-3.141592" upper="3.141592" velocity="3" />
  </joint>
  <link name="act1Seg8helper_shape">
    <visual>
      <origin rpy="-1.5707963267948966 0 0" xyz="0 0 0.0" />
      <geometry>
        <cylinder length="0.5" radius="0.25" />
      </geometry>
      <material name="blue">
        <color rgba="0.3 0.0 1 1.0" />
      </material>
    </visual>
    <collision>
      <origin rpy="-1.5707963267948966 0 0" xyz="0 0 0.0" />
      <geometry>
        <cylinder length="0.5" radius="0.25" />
      </geometry>
    </collision>
    <inertial>
      <mass value="5.5467879993584955e-05" />
      <inertia ixx="0.001" ixy="0.0" ixz="0.0" iyy="0.001" iyz="0.0" izz="0.001" />
      <origin rpy="-1.5707963267948966 0 0" xyz="0 0 0.0" />
    </inertial>
  </link>
  <joint name="act1Seg7_to_act1Seg8_ax1helper_shape" type="fixed">
    <parent link="act1Seg7" />
    <child link="act1Seg8helper_shape" />
    <origin rpy="0 0 0" xyz="0 0 0.5" />
    <axis xyz="1 0 0" />
  </joint>
  <link name="act1Seg9">
    <visual>
      <origin rpy="0 0 0" xyz="0 0 0.25" />
      <geometry>
        <box size="0.5 0.5 0.5" />
      </geometry>
      <material name="blue">
        <color rgba="0.3 0.0 1 1.0" />
      </material>
    </visual>
    <collision>
      <origin rpy="0 0 0" xyz="0 0 0.25" />
      <geometry>
        <box size="0.5 0.5 0.5" />
      </geometry>
    </collision>
    <inertial>
      <mass value="0.055467879993584955" />
      <inertia ixx="1" ixy="0" ixz="0" iyy="1" iyz="0" izz="1" />
      <origin rpy="0 0 0" xyz="0 0 0.25" />
    </inertial>
  </link>
  <joint name="act1Seg8_to_act1Seg9_ax0" type="revolute">
    <parent link="act1Seg8" />
    <child link="act1Seg9" />
    <origin rpy="0 0 0" xyz="0 0 0.5" />
    <axis xyz="1 0 0" />
    <limit effort="100" lower="-1" upper="1" velocity="3" />
  </joint>
  <link name="act1Seg9helper_shape">
    <visual>
      <origin rpy="0 -1.5707963267948966 0" xyz="0 0 0.0" />
      <geometry>
        <cylinder length="0.5" radius="0.25" />
      </geometry>
      <material name="blue">
        <color rgba="0.3 0.0 1 1.0" />
      </material>
    </visual>
    <collision>
      <origin rpy="0 -1.5707963267948966 0" xyz="0 0 0.0" />
      <geometry>
        <cylinder length="0.5" radius="0.25" />
      </geometry>
    </collision>
    <inertial>
      <mass value="5.5467879993584955e-05" />
      <inertia ixx="0.001" ixy="0.0" ixz="0.0" iyy="0.001" iyz="0.0" izz="0.001" />
      <origin rpy="0 -1.5707963267948966 0" xyz="0 0 0.0" />
    </inertial>
  </link>
  <joint name="act1Seg8_to_act1Seg9_ax0helper_shape" type="fixed">
    <parent link="act1Seg8" />
    <child link="act1Seg9helper_shape" />
    <origin rpy="0 0 0" xyz="0 0 0.5" />
    <axis xyz="1 0 0" />
  </joint>
  <link name="act1Seg10">
    <visual>
      <origin rpy="0 0 0" xyz="0 0 0.25" />
      <geometry>
        <box size="0.5 0.5 0.5" />
      </geometry>
      <material name="blue">
        <color rgba="0.3 0.0 1 1.0" />
      </material>
    </visual>
    <collision>
      <origin rpy="0 0 0" xyz="0 0 0.25" />
      <geometry>
        <box size="0.5 0.5 0.5" />
      </geometry>
    </collision>
    <inertial>
      <mass value="0.055467879993584955" />
      <inertia ixx="1" ixy="0" ixz="0" iyy="1" iyz="0" izz="1" />
      <origin rpy="0 0 0" xyz="0 0 0.25" />
    </inertial>
  </link>
  <joint name="act1Seg9_to_act1Seg10_ax1" type="revolute">
    <parent link="act1Seg9" />
    <child link="act1Seg10" />
    <origin rpy="0 0 0" xyz="0 0 0.5" />
    <axis xyz="0 1 0" />
    <limit effort="100" lower="-3.141592" upper="3.141592" velocity="3" />
  </joint>
  <link name="act1Seg10helper_shape">
    <visual>
      <origin rpy="-1.5707963267948966 0 0" xyz="0 0 0.0" />
      <geometry>
        <cylinder length="0.5" radius="0.25" />
      </geometry>
      <material name="blue">
        <color rgba="0.3 0.0 1 1.0" />
      </material>
    </visual>
    <collision>
      <origin rpy="-1.5707963267948966 0 0" xyz="0 0 0.0" />
      <geometry>
        <cylinder length="0.5" radius="0.25" />
      </geometry>
    </collision>
    <inertial>
      <mass value="5.5467879993584955e-05" />
      <inertia ixx="0.001" ixy="0.0" ixz="0.0" iyy="0.001" iyz="0.0" izz="0.001" />
      <origin rpy="-1.5707963267948966 0 0" xyz="0 0 0.0" />
    </inertial>
  </link>
  <joint name="act1Seg9_to_act1Seg10_ax1helper_shape" type="fixed">
    <parent link="act1Seg9" />
    <child link="act1Seg10helper_shape" />
    <origin rpy="0 0 0" xyz="0 0 0.5" />
    <axis xyz="1 0 0" />
  </joint>
  <link name="act1Seg11">
    <visual>
      <origin rpy="0 0 0" xyz="0 0 0.25" />
      <geometry>
        <box size="0.5 0.5 0.5" />
      </geometry>
      <material name="blue">
        <color rgba="0.3 0.0 1 1.0" />
      </material>
    </visual>
    <collision>
      <origin rpy="0 0 0" xyz="0 0 0.25" />
      <geometry>
        <box size="0.5 0.5 0.5" />
      </geometry>
    </collision>
    <inertial>
      <mass value="0.055467879993584955" />
      <inertia ixx="1" ixy="0" ixz="0" iyy="1" iyz="0" izz="1" />
      <origin rpy="0 0 0" xyz="0 0 0.25" />
    </inertial>
  </link>
  <joint name="act1Seg10_to_act1Seg11_ax0" type="revolute">
    <parent link="act1Seg10" />
    <child link="act1Seg11" />
    <origin rpy="0 0 0" xyz="0 0 0.5" />
    <axis xyz="1 0 0" />
    <limit effort="100" lower="-1" upper="1" velocity="3" />
  </joint>
  <link name="act1Seg11helper_shape">
    <visual>
      <origin rpy="0 -1.5707963267948966 0" xyz="0 0 0.0" />
      <geometry>
        <cylinder length="0.5" radius="0.25" />
      </geometry>
      <material name="blue">
        <color rgba="0.3 0.0 1 1.0" />
      </material>
    </visual>
    <collision>
      <origin rpy="0 -1.5707963267948966 0" xyz="0 0 0.0" />
      <geometry>
        <cylinder length="0.5" radius="0.25" />
      </geometry>
    </collision>
    <inertial>
      <mass value="5.5467879993584955e-05" />
      <inertia ixx="0.001" ixy="0.0" ixz="0.0" iyy="0.001" iyz="0.0" izz="0.001" />
      <origin rpy="0 -1.5707963267948966 0" xyz="0 0 0.0" />
    </inertial>
  </link>
  <joint name="act1Seg10_to_act1Seg11_ax0helper_shape" type="fixed">
    <parent link="act1Seg10" />
    <child link="act1Seg11helper_shape" />
    <origin rpy="0 0 0" xyz="0 0 0.5" />
    <axis xyz="1 0 0" />
  </joint>
  <link name="act1Seg12">
    <visual>
      <origin rpy="0 0 0" xyz="0 0 0.25" />
      <geometry>
        <box size="0.5 0.5 0.5" />
      </geometry>
      <material name="blue">
        <color rgba="0.3 0.0 1 1.0" />
      </material>
    </visual>
    <collision>
      <origin rpy="0 0 0" xyz="0 0 0.25" />
      <geometry>
        <box size="0.5 0.5 0.5" />
      </geometry>
    </collision>
    <inertial>
      <mass value="0.055467879993584955" />
      <inertia ixx="1" ixy="0" ixz="0" iyy="1" iyz="0" izz="1" />
      <origin rpy="0 0 0" xyz="0 0 0.25" />
    </inertial>
  </link>
  <joint name="act1Seg11_to_act1Seg12_ax1" type="revolute">
    <parent link="act1Seg11" />
    <child link="act1Seg12" />
    <origin rpy="0 0 0" xyz="0 0 0.5" />
    <axis xyz="0 1 0" />
    <limit effort="100" lower="-3.141592" upper="3.141592" velocity="3" />
  </joint>
  <link name="act1Seg12helper_shape">
    <visual>
      <origin rpy="-1.5707963267948966 0 0" xyz="0 0 0.0" />
      <geometry>
        <cylinder length="0.5" radius="0.25" />
      </geometry>
      <material name="blue">
        <color rgba="0.3 0.0 1 1.0" />
      </material>
    </visual>
    <collision>
      <origin rpy="-1.5707963267948966 0 0" xyz="0 0 0.0" />
      <geometry>
        <cylinder length="0.5" radius="0.25" />
      </geometry>
    </collision>
    <inertial>
      <mass value="5.5467879993584955e-05" />
      <inertia ixx="0.001" ixy="0.0" ixz="0.0" iyy="0.001" iyz="0.0" izz="0.001" />
      <origin rpy="-1.5707963267948966 0 0" xyz="0 0 0.0" />
    </inertial>
  </link>
  <joint name="act1Seg11_to_act1Seg12_ax1helper_shape" type="fixed">
    <parent link="act1Seg11" />
    <child link="act1Seg12helper_shape" />
    <origin rpy="0 0 0" xyz="0 0 0.5" />
    <axis xyz="1 0 0" />
  </joint>
  <link name="act1Seg13">
    <visual>
      <origin rpy="0 0 0" xyz="0 0 0.25" />
      <geometry>
        <box size="0.5 0.5 0.5" />
      </geometry>
      <material name="blue">
        <color rgba="0.3 0.0 1 1.0" />
      </material>
    </visual>
    <collision>
      <origin rpy="0 0 0" xyz="0 0 0.25" />
      <geometry>
        <box size="0.5 0.5 0.5" />
      </geometry>
    </collision>
    <inertial>
      <mass value="0.055467879993584955" />
      <inertia ixx="1" ixy="0" ixz="0" iyy="1" iyz="0" izz="1" />
      <origin rpy="0 0 0" xyz="0 0 0.25" />
    </inertial>
  </link>
  <joint name="act1Seg12_to_act1Seg13_ax0" type="revolute">
    <parent link="act1Seg12" />
    <child link="act1Seg13" />
    <origin rpy="0 0 0" xyz="0 0 0.5" />
    <axis xyz="1 0 0" />
    <limit effort="100" lower="-1" upper="1" velocity="3" />
  </joint>
  <link name="act1Seg13helper_shape">
    <visual>
      <origin rpy="0 -1.5707963267948966 0" xyz="0 0 0.0" />
      <geometry>
        <cylinder length="0.5" radius="0.25" />
      </geometry>
      <material name="blue">
        <color rgba="0.3 0.0 1 1.0" />
      </material>
    </visual>
    <collision>
      <origin rpy="0 -1.5707963267948966 0" xyz="0 0 0.0" />
      <geometry>
        <cylinder length="0.5" radius="0.25" />
      </geometry>
    </collision>
    <inertial>
      <mass value="5.5467879993584955e-05" />
      <inertia ixx="0.001" ixy="0.0" ixz="0.0" iyy="0.001" iyz="0.0" izz="0.001" />
      <origin rpy="0 -1.5707963267948966 0" xyz="0 0 0.0" />
    </inertial>
  </link>
  <joint name="act1Seg12_to_act1Seg13_ax0helper_shape" type="fixed">
    <parent link="act1Seg12" />
    <child link="act1Seg13helper_shape" />
    <origin rpy="0 0 0" xyz="0 0 0.5" />
    <axis xyz="1 0 0" />
  </joint>
  <link name="act1Seg14">
    <visual>
      <origin rpy="0 0 0" xyz="0 0 0.125" />
      <geometry>
        <box size="0.5 0.5 0.25" />
      </geometry>
      <material name="blue">
        <color rgba="0.3 0.0 1 1.0" />
      </material>
    </visual>
    <collision>
      <origin rpy="0 0 0" xyz="0 0 0.125" />
      <geometry>
        <box size="0.5 0.5 0.25" />
      </geometry>
    </collision>
    <inertial>
      <mass value="0.055467879993584955" />
      <inertia ixx="1" ixy="0" ixz="0" iyy="1" iyz="0" izz="1" />
      <origin rpy="0 0 0" xyz="0 0 0.125" />
    </inertial>
  </link>
  <joint name="act1Seg13_to_act1Seg14_ax1" type="revolute">
    <parent link="act1Seg13" />
    <child link="act1Seg14" />
    <origin rpy="0 0 0" xyz="0 0 0.5" />
    <axis xyz="0 1 0" />
    <limit effort="100" lower="-3.141592" upper="3.141592" velocity="3" />
  </joint>
  <link name="act1Seg14helper_shape">
    <visual>
      <origin rpy="-1.5707963267948966 0 0" xyz="0 0 0.0" />
      <geometry>
        <cylinder length="0.5" radius="0.25" />
      </geometry>
      <material name="blue">
        <color rgba="0.3 0.0 1 1.0" />
      </material>
    </visual>
    <collision>
      <origin rpy="-1.5707963267948966 0 0" xyz="0 0 0.0" />
      <geometry>
        <cylinder length="0.5" radius="0.25" />
      </geometry>
    </collision>
    <inertial>
      <mass value="5.5467879993584955e-05" />
      <inertia ixx="0.001" ixy="0.0" ixz="0.0" iyy="0.001" iyz="0.0" izz="0.001" />
      <origin rpy="-1.5707963267948966 0 0" xyz="0 0 0.0" />
    </inertial>
  </link>
  <joint name="act1Seg13_to_act1Seg14_ax1helper_shape" type="fixed">
    <parent link="act1Seg13" />
    <child link="act1Seg14helper_shape" />
    <origin rpy="0 0 0" xyz="0 0 0.5" />
    <axis xyz="1 0 0" />
  </joint>
</robot>
